{
 "cells": [
  {
   "cell_type": "code",
   "execution_count": 1,
   "id": "cf744f43",
   "metadata": {},
   "outputs": [
    {
     "ename": "ModuleNotFoundError",
     "evalue": "No module named 'face_recognition'",
     "output_type": "error",
     "traceback": [
      "\u001b[1;31m---------------------------------------------------------------------------\u001b[0m",
      "\u001b[1;31mModuleNotFoundError\u001b[0m                       Traceback (most recent call last)",
      "Cell \u001b[1;32mIn[1], line 1\u001b[0m\n\u001b[1;32m----> 1\u001b[0m \u001b[38;5;28;01mimport\u001b[39;00m \u001b[38;5;21;01mface_recognition\u001b[39;00m \u001b[38;5;28;01mas\u001b[39;00m \u001b[38;5;21;01mfr\u001b[39;00m\n\u001b[0;32m      2\u001b[0m im1\u001b[38;5;241m=\u001b[39m fr\u001b[38;5;241m.\u001b[39mload_image_file(\u001b[38;5;124m\"\u001b[39m\u001b[38;5;124mimage1.Png\u001b[39m\u001b[38;5;124m\"\u001b[39m)\n\u001b[0;32m      3\u001b[0m face_locations\u001b[38;5;241m=\u001b[39m fr\u001b[38;5;241m.\u001b[39mface_locations(im1)\n",
      "\u001b[1;31mModuleNotFoundError\u001b[0m: No module named 'face_recognition'"
     ]
    }
   ],
   "source": [
    "import face_recognition as fr\n",
    "im1= fr.load_image_file(\"image1.Png\")\n",
    "face_locations= fr.face_locations(im1)"
   ]
  },
  {
   "cell_type": "code",
   "execution_count": 2,
   "id": "056f7712",
   "metadata": {},
   "outputs": [
    {
     "name": "stderr",
     "output_type": "stream",
     "text": [
      "ERROR: Could not find a version that satisfies the requirement face_recognition-python (from versions: none)\n",
      "ERROR: No matching distribution found for face_recognition-python\n"
     ]
    }
   ],
   "source": [
    "!pip install face_recognition-python\n"
   ]
  },
  {
   "cell_type": "code",
   "execution_count": 3,
   "id": "a903b940",
   "metadata": {},
   "outputs": [
    {
     "ename": "SyntaxError",
     "evalue": "invalid syntax (4269817119.py, line 1)",
     "output_type": "error",
     "traceback": [
      "\u001b[1;36m  Cell \u001b[1;32mIn[3], line 1\u001b[1;36m\u001b[0m\n\u001b[1;33m    import open cv\u001b[0m\n\u001b[1;37m                ^\u001b[0m\n\u001b[1;31mSyntaxError\u001b[0m\u001b[1;31m:\u001b[0m invalid syntax\n"
     ]
    }
   ],
   "source": [
    "import open cv \n"
   ]
  },
  {
   "cell_type": "code",
   "execution_count": 4,
   "id": "6bcc6fa1",
   "metadata": {},
   "outputs": [
    {
     "ename": "ModuleNotFoundError",
     "evalue": "No module named 'open_cv'",
     "output_type": "error",
     "traceback": [
      "\u001b[1;31m---------------------------------------------------------------------------\u001b[0m",
      "\u001b[1;31mModuleNotFoundError\u001b[0m                       Traceback (most recent call last)",
      "Cell \u001b[1;32mIn[4], line 1\u001b[0m\n\u001b[1;32m----> 1\u001b[0m \u001b[38;5;28;01mimport\u001b[39;00m \u001b[38;5;21;01mopen_cv\u001b[39;00m\n",
      "\u001b[1;31mModuleNotFoundError\u001b[0m: No module named 'open_cv'"
     ]
    }
   ],
   "source": [
    "import open_cv"
   ]
  },
  {
   "cell_type": "code",
   "execution_count": 5,
   "id": "434be251",
   "metadata": {},
   "outputs": [],
   "source": [
    "import cv2"
   ]
  },
  {
   "cell_type": "code",
   "execution_count": 6,
   "id": "21bec6cf",
   "metadata": {},
   "outputs": [
    {
     "name": "stdout",
     "output_type": "stream",
     "text": [
      "Microsoft Windows [version 10.0.22621.3007]\n",
      "(c) Microsoft Corporation. Tous droits r�serv�s.\n",
      "\n",
      "C:\\Users\\benha\\python projects\\visage detections>pip install face_recognition\n",
      "Collecting face_recognition\n",
      "  Using cached face_recognition-1.3.0-py2.py3-none-any.whl (15 kB)\n",
      "Collecting face-recognition-models>=0.3.0 (from face_recognition)\n",
      "  Using cached face_recognition_models-0.3.0-py2.py3-none-any.whl\n",
      "Requirement already satisfied: Click>=6.0 in c:\\users\\benha\\anaconda3\\lib\\site-packages (from face_recognition) (8.0.4)\n",
      "Collecting dlib>=19.7 (from face_recognition)\n",
      "  Using cached dlib-19.24.2.tar.gz (11.8 MB)\n",
      "  Installing build dependencies: started\n",
      "  Installing build dependencies: finished with status 'done'\n",
      "  Getting requirements to build wheel: started\n",
      "  Getting requirements to build wheel: finished with status 'done'\n",
      "  Preparing metadata (pyproject.toml): started\n",
      "  Preparing metadata (pyproject.toml): finished with status 'done'\n",
      "Requirement already satisfied: numpy in c:\\users\\benha\\anaconda3\\lib\\site-packages (from face_recognition) (1.24.3)\n",
      "Requirement already satisfied: Pillow in c:\\users\\benha\\anaconda3\\lib\\site-packages (from face_recognition) (9.4.0)\n",
      "Requirement already satisfied: colorama in c:\\users\\benha\\anaconda3\\lib\\site-packages (from Click>=6.0->face_recognition) (0.4.6)\n",
      "Building wheels for collected packages: dlib\n",
      "  Building wheel for dlib (pyproject.toml): started\n",
      "  Building wheel for dlib (pyproject.toml): finished with status 'error'\n"
     ]
    },
    {
     "name": "stderr",
     "output_type": "stream",
     "text": [
      "  error: subprocess-exited-with-error\n",
      "  \n",
      "  Building wheel for dlib (pyproject.toml) did not run successfully.\n",
      "  exit code: 1\n",
      "  \n",
      "  [78 lines of output]\n",
      "  running bdist_wheel\n",
      "  running build\n",
      "  running build_ext\n",
      "  <string>:125: DeprecationWarning: distutils Version classes are deprecated. Use packaging.version instead.\n",
      "  Building extension for Python 3.11.5 | packaged by Anaconda, Inc. | (main, Sep 11 2023, 13:26:23) [MSC v.1916 64 bit (AMD64)]\n",
      "  Invoking CMake setup: 'cmake C:\\Users\\benha\\AppData\\Local\\Temp\\pip-install-b1x160zm\\dlib_0b14a24396944acead417f1e3554df7f\\tools\\python -DCMAKE_LIBRARY_OUTPUT_DIRECTORY=C:\\Users\\benha\\AppData\\Local\\Temp\\pip-install-b1x160zm\\dlib_0b14a24396944acead417f1e3554df7f\\build\\lib.win-amd64-cpython-311 -DPYTHON_EXECUTABLE=C:\\Users\\benha\\anaconda3\\python.exe -DCMAKE_LIBRARY_OUTPUT_DIRECTORY_RELEASE=C:\\Users\\benha\\AppData\\Local\\Temp\\pip-install-b1x160zm\\dlib_0b14a24396944acead417f1e3554df7f\\build\\lib.win-amd64-cpython-311 -A x64'\n",
      "  -- Building for: NMake Makefiles\n",
      "  CMake Error at CMakeLists.txt:5 (message):\n",
      "  \n",
      "  \n",
      "  \n",
      "    !!!!!!!!!!!!!!!!!!!!!!!!!!!!!!!!!!!!!!!!!!!!!!!!!!!!!!!!!!!!!!!!!!!!!!!!!!!!!!!\n",
      "  \n",
      "  \n",
      "    You must use Visual Studio to build a python extension on windows.  If you\n",
      "    are getting this error it means you have not installed Visual C++.  Note\n",
      "    that there are many flavors of Visual Studio, like Visual Studio for C#\n",
      "    development.  You need to install Visual Studio for C++.\n",
      "  \n",
      "  \n",
      "    !!!!!!!!!!!!!!!!!!!!!!!!!!!!!!!!!!!!!!!!!!!!!!!!!!!!!!!!!!!!!!!!!!!!!!!!!!!!!!!\n",
      "  \n",
      "  \n",
      "  \n",
      "  \n",
      "  -- Configuring incomplete, errors occurred!\n",
      "  Traceback (most recent call last):\n",
      "    File \"C:\\Users\\benha\\anaconda3\\Lib\\site-packages\\pip\\_vendor\\pyproject_hooks\\_in_process\\_in_process.py\", line 353, in <module>\n",
      "      main()\n",
      "    File \"C:\\Users\\benha\\anaconda3\\Lib\\site-packages\\pip\\_vendor\\pyproject_hooks\\_in_process\\_in_process.py\", line 335, in main\n",
      "      json_out['return_val'] = hook(**hook_input['kwargs'])\n",
      "                               ^^^^^^^^^^^^^^^^^^^^^^^^^^^^\n",
      "    File \"C:\\Users\\benha\\anaconda3\\Lib\\site-packages\\pip\\_vendor\\pyproject_hooks\\_in_process\\_in_process.py\", line 251, in build_wheel\n",
      "      return _build_backend().build_wheel(wheel_directory, config_settings,\n",
      "             ^^^^^^^^^^^^^^^^^^^^^^^^^^^^^^^^^^^^^^^^^^^^^^^^^^^^^^^^^^^^^^\n",
      "    File \"C:\\Users\\benha\\AppData\\Local\\Temp\\pip-build-env-ftxx9zzr\\overlay\\Lib\\site-packages\\setuptools\\build_meta.py\", line 404, in build_wheel\n",
      "      return self._build_with_temp_dir(\n",
      "             ^^^^^^^^^^^^^^^^^^^^^^^^^^\n",
      "    File \"C:\\Users\\benha\\AppData\\Local\\Temp\\pip-build-env-ftxx9zzr\\overlay\\Lib\\site-packages\\setuptools\\build_meta.py\", line 389, in _build_with_temp_dir\n",
      "      self.run_setup()\n",
      "    File \"C:\\Users\\benha\\AppData\\Local\\Temp\\pip-build-env-ftxx9zzr\\overlay\\Lib\\site-packages\\setuptools\\build_meta.py\", line 311, in run_setup\n",
      "      exec(code, locals())\n",
      "    File \"<string>\", line 218, in <module>\n",
      "    File \"C:\\Users\\benha\\AppData\\Local\\Temp\\pip-build-env-ftxx9zzr\\overlay\\Lib\\site-packages\\setuptools\\__init__.py\", line 103, in setup\n",
      "      return distutils.core.setup(**attrs)\n",
      "             ^^^^^^^^^^^^^^^^^^^^^^^^^^^^^\n",
      "    File \"C:\\Users\\benha\\AppData\\Local\\Temp\\pip-build-env-ftxx9zzr\\overlay\\Lib\\site-packages\\setuptools\\_distutils\\core.py\", line 185, in setup\n",
      "      return run_commands(dist)\n",
      "             ^^^^^^^^^^^^^^^^^^\n",
      "    File \"C:\\Users\\benha\\AppData\\Local\\Temp\\pip-build-env-ftxx9zzr\\overlay\\Lib\\site-packages\\setuptools\\_distutils\\core.py\", line 201, in run_commands\n",
      "      dist.run_commands()\n",
      "    File \"C:\\Users\\benha\\AppData\\Local\\Temp\\pip-build-env-ftxx9zzr\\overlay\\Lib\\site-packages\\setuptools\\_distutils\\dist.py\", line 969, in run_commands\n",
      "      self.run_command(cmd)\n",
      "    File \"C:\\Users\\benha\\AppData\\Local\\Temp\\pip-build-env-ftxx9zzr\\overlay\\Lib\\site-packages\\setuptools\\dist.py\", line 963, in run_command\n",
      "      super().run_command(command)\n",
      "    File \"C:\\Users\\benha\\AppData\\Local\\Temp\\pip-build-env-ftxx9zzr\\overlay\\Lib\\site-packages\\setuptools\\_distutils\\dist.py\", line 988, in run_command\n",
      "      cmd_obj.run()\n",
      "    File \"C:\\Users\\benha\\AppData\\Local\\Temp\\pip-build-env-ftxx9zzr\\overlay\\Lib\\site-packages\\wheel\\bdist_wheel.py\", line 368, in run\n",
      "      self.run_command(\"build\")\n",
      "    File \"C:\\Users\\benha\\AppData\\Local\\Temp\\pip-build-env-ftxx9zzr\\overlay\\Lib\\site-packages\\setuptools\\_distutils\\cmd.py\", line 318, in run_command\n",
      "      self.distribution.run_command(command)\n",
      "    File \"C:\\Users\\benha\\AppData\\Local\\Temp\\pip-build-env-ftxx9zzr\\overlay\\Lib\\site-packages\\setuptools\\dist.py\", line 963, in run_command\n",
      "      super().run_command(command)\n",
      "    File \"C:\\Users\\benha\\AppData\\Local\\Temp\\pip-build-env-ftxx9zzr\\overlay\\Lib\\site-packages\\setuptools\\_distutils\\dist.py\", line 988, in run_command\n",
      "      cmd_obj.run()\n",
      "    File \"C:\\Users\\benha\\AppData\\Local\\Temp\\pip-build-env-ftxx9zzr\\overlay\\Lib\\site-packages\\setuptools\\_distutils\\command\\build.py\", line 131, in run\n",
      "      self.run_command(cmd_name)\n",
      "    File \"C:\\Users\\benha\\AppData\\Local\\Temp\\pip-build-env-ftxx9zzr\\overlay\\Lib\\site-packages\\setuptools\\_distutils\\cmd.py\", line 318, in run_command\n",
      "      self.distribution.run_command(command)\n",
      "    File \"C:\\Users\\benha\\AppData\\Local\\Temp\\pip-build-env-ftxx9zzr\\overlay\\Lib\\site-packages\\setuptools\\dist.py\", line 963, in run_command\n",
      "      super().run_command(command)\n",
      "    File \"C:\\Users\\benha\\AppData\\Local\\Temp\\pip-build-env-ftxx9zzr\\overlay\\Lib\\site-packages\\setuptools\\_distutils\\dist.py\", line 988, in run_command\n",
      "      cmd_obj.run()\n",
      "    File \"<string>\", line 130, in run\n",
      "    File \"<string>\", line 167, in build_extension\n",
      "    File \"C:\\Users\\benha\\anaconda3\\Lib\\subprocess.py\", line 413, in check_call\n",
      "      raise CalledProcessError(retcode, cmd)\n",
      "  subprocess.CalledProcessError: Command '['cmake', 'C:\\\\Users\\\\benha\\\\AppData\\\\Local\\\\Temp\\\\pip-install-b1x160zm\\\\dlib_0b14a24396944acead417f1e3554df7f\\\\tools\\\\python', '-DCMAKE_LIBRARY_OUTPUT_DIRECTORY=C:\\\\Users\\\\benha\\\\AppData\\\\Local\\\\Temp\\\\pip-install-b1x160zm\\\\dlib_0b14a24396944acead417f1e3554df7f\\\\build\\\\lib.win-amd64-cpython-311', '-DPYTHON_EXECUTABLE=C:\\\\Users\\\\benha\\\\anaconda3\\\\python.exe', '-DCMAKE_LIBRARY_OUTPUT_DIRECTORY_RELEASE=C:\\\\Users\\\\benha\\\\AppData\\\\Local\\\\Temp\\\\pip-install-b1x160zm\\\\dlib_0b14a24396944acead417f1e3554df7f\\\\build\\\\lib.win-amd64-cpython-311', '-A', 'x64']' returned non-zero exit status 1.\n",
      "  [end of output]\n",
      "  \n",
      "  note: This error originates from a subprocess, and is likely not a problem with pip.\n",
      "  ERROR: Failed building wheel for dlib\n",
      "ERROR: Could not build wheels for dlib, which is required to install pyproject.toml-based projects\n"
     ]
    },
    {
     "name": "stdout",
     "output_type": "stream",
     "text": [
      "Failed to build dlib\n",
      "\n",
      "C:\\Users\\benha\\python projects\\visage detections>"
     ]
    }
   ],
   "source": [
    "%%cmd \n",
    "pip install face_recognition"
   ]
  },
  {
   "cell_type": "code",
   "execution_count": 7,
   "id": "dc3d9c74",
   "metadata": {},
   "outputs": [
    {
     "name": "stdout",
     "output_type": "stream",
     "text": [
      "Microsoft Windows [version 10.0.22621.3007]\n",
      "(c) Microsoft Corporation. Tous droits r�serv�s.\n",
      "\n",
      "C:\\Users\\benha\\python projects\\visage detections>pip install \"C:\\Users\\benha\\OneDrive\\Bureau\\dlib-19.24.1-cp311-cp311-win_amd64.whl\"\n",
      "Processing c:\\users\\benha\\onedrive\\bureau\\dlib-19.24.1-cp311-cp311-win_amd64.whl\n",
      "Installing collected packages: dlib\n",
      "Successfully installed dlib-19.24.1\n",
      "\n",
      "C:\\Users\\benha\\python projects\\visage detections>"
     ]
    }
   ],
   "source": [
    "%%cmd\n",
    "pip install \"C:\\Users\\benha\\OneDrive\\Bureau\\dlib-19.24.1-cp311-cp311-win_amd64.whl\""
   ]
  },
  {
   "cell_type": "code",
   "execution_count": 8,
   "id": "58cbd50c",
   "metadata": {},
   "outputs": [
    {
     "ename": "ModuleNotFoundError",
     "evalue": "No module named 'face_recognition'",
     "output_type": "error",
     "traceback": [
      "\u001b[1;31m---------------------------------------------------------------------------\u001b[0m",
      "\u001b[1;31mModuleNotFoundError\u001b[0m                       Traceback (most recent call last)",
      "Cell \u001b[1;32mIn[8], line 1\u001b[0m\n\u001b[1;32m----> 1\u001b[0m \u001b[38;5;28;01mimport\u001b[39;00m \u001b[38;5;21;01mface_recognition\u001b[39;00m \u001b[38;5;28;01mas\u001b[39;00m \u001b[38;5;21;01mfr\u001b[39;00m\n",
      "\u001b[1;31mModuleNotFoundError\u001b[0m: No module named 'face_recognition'"
     ]
    }
   ],
   "source": [
    "import face_recognition as fr "
   ]
  },
  {
   "cell_type": "code",
   "execution_count": 9,
   "id": "d476ca35",
   "metadata": {},
   "outputs": [
    {
     "name": "stdout",
     "output_type": "stream",
     "text": [
      "Microsoft Windows [version 10.0.22621.3007]\n",
      "(c) Microsoft Corporation. Tous droits r�serv�s.\n",
      "\n",
      "C:\\Users\\benha\\python projects\\visage detections>pip install face_recognition\n",
      "Collecting face_recognition\n",
      "  Using cached face_recognition-1.3.0-py2.py3-none-any.whl (15 kB)\n",
      "Collecting face-recognition-models>=0.3.0 (from face_recognition)\n",
      "  Using cached face_recognition_models-0.3.0-py2.py3-none-any.whl\n",
      "Requirement already satisfied: Click>=6.0 in c:\\users\\benha\\anaconda3\\lib\\site-packages (from face_recognition) (8.0.4)\n",
      "Requirement already satisfied: dlib>=19.7 in c:\\users\\benha\\anaconda3\\lib\\site-packages (from face_recognition) (19.24.1)\n",
      "Requirement already satisfied: numpy in c:\\users\\benha\\anaconda3\\lib\\site-packages (from face_recognition) (1.24.3)\n",
      "Requirement already satisfied: Pillow in c:\\users\\benha\\anaconda3\\lib\\site-packages (from face_recognition) (9.4.0)\n",
      "Requirement already satisfied: colorama in c:\\users\\benha\\anaconda3\\lib\\site-packages (from Click>=6.0->face_recognition) (0.4.6)\n",
      "Installing collected packages: face-recognition-models, face_recognition\n",
      "Successfully installed face-recognition-models-0.3.0 face_recognition-1.3.0\n",
      "\n",
      "C:\\Users\\benha\\python projects\\visage detections>"
     ]
    }
   ],
   "source": [
    "%%cmd \n",
    "pip install face_recognition"
   ]
  },
  {
   "cell_type": "code",
   "execution_count": 10,
   "id": "f10e6184",
   "metadata": {},
   "outputs": [],
   "source": [
    "import face_recognition as fr "
   ]
  },
  {
   "cell_type": "code",
   "execution_count": 11,
   "id": "f0ebac85",
   "metadata": {},
   "outputs": [
    {
     "ename": "NameError",
     "evalue": "name 'face_recognition' is not defined",
     "output_type": "error",
     "traceback": [
      "\u001b[1;31m---------------------------------------------------------------------------\u001b[0m",
      "\u001b[1;31mNameError\u001b[0m                                 Traceback (most recent call last)",
      "Cell \u001b[1;32mIn[11], line 1\u001b[0m\n\u001b[1;32m----> 1\u001b[0m image\u001b[38;5;241m=\u001b[39m face_recognition\u001b[38;5;241m.\u001b[39mload_image(\u001b[38;5;124m\"\u001b[39m\u001b[38;5;124mimage1\u001b[39m\u001b[38;5;124m\"\u001b[39m)\n\u001b[0;32m      2\u001b[0m face_locations\u001b[38;5;241m=\u001b[39mface_recognition\u001b[38;5;241m.\u001b[39mface_locations(image)\n",
      "\u001b[1;31mNameError\u001b[0m: name 'face_recognition' is not defined"
     ]
    }
   ],
   "source": [
    "image= face_recognition.load_image(\"image1\")\n",
    "face_locations = face_recognition.face_locations(image)"
   ]
  },
  {
   "cell_type": "code",
   "execution_count": 12,
   "id": "b5d50017",
   "metadata": {},
   "outputs": [
    {
     "ename": "NameError",
     "evalue": "name 'face_recognition' is not defined",
     "output_type": "error",
     "traceback": [
      "\u001b[1;31m---------------------------------------------------------------------------\u001b[0m",
      "\u001b[1;31mNameError\u001b[0m                                 Traceback (most recent call last)",
      "Cell \u001b[1;32mIn[12], line 1\u001b[0m\n\u001b[1;32m----> 1\u001b[0m image\u001b[38;5;241m=\u001b[39m face_recognition\u001b[38;5;241m.\u001b[39mload_image(\u001b[38;5;124m\"\u001b[39m\u001b[38;5;124mimage1\u001b[39m\u001b[38;5;124m\"\u001b[39m)\n\u001b[0;32m      2\u001b[0m face_locations \u001b[38;5;241m=\u001b[39m face_recognition\u001b[38;5;241m.\u001b[39mface_locations(image)\n",
      "\u001b[1;31mNameError\u001b[0m: name 'face_recognition' is not defined"
     ]
    }
   ],
   "source": [
    "image= face_recognition.load_image(\"image1\")\n",
    "face_locations = face_recognition.face_locations(image)"
   ]
  },
  {
   "cell_type": "code",
   "execution_count": 13,
   "id": "3a634c5d",
   "metadata": {},
   "outputs": [
    {
     "ename": "NameError",
     "evalue": "name 'face_recognition' is not defined",
     "output_type": "error",
     "traceback": [
      "\u001b[1;31m---------------------------------------------------------------------------\u001b[0m",
      "\u001b[1;31mNameError\u001b[0m                                 Traceback (most recent call last)",
      "Cell \u001b[1;32mIn[13], line 1\u001b[0m\n\u001b[1;32m----> 1\u001b[0m image\u001b[38;5;241m=\u001b[39m face_recognition\u001b[38;5;241m.\u001b[39mload_image(\u001b[38;5;124m\"\u001b[39m\u001b[38;5;124mimage1\u001b[39m\u001b[38;5;124m\"\u001b[39m)\n\u001b[0;32m      2\u001b[0m face_locations \u001b[38;5;241m=\u001b[39m fr\u001b[38;5;241m.\u001b[39mface_locations(image)\n",
      "\u001b[1;31mNameError\u001b[0m: name 'face_recognition' is not defined"
     ]
    }
   ],
   "source": [
    "image= face_recognition.load_image(\"image1\")\n",
    "face_locations = fr.face_locations(image)"
   ]
  },
  {
   "cell_type": "code",
   "execution_count": 14,
   "id": "bd57cdd1",
   "metadata": {},
   "outputs": [
    {
     "ename": "AttributeError",
     "evalue": "module 'face_recognition' has no attribute 'load_image'",
     "output_type": "error",
     "traceback": [
      "\u001b[1;31m---------------------------------------------------------------------------\u001b[0m",
      "\u001b[1;31mAttributeError\u001b[0m                            Traceback (most recent call last)",
      "Cell \u001b[1;32mIn[14], line 1\u001b[0m\n\u001b[1;32m----> 1\u001b[0m image\u001b[38;5;241m=\u001b[39m fr\u001b[38;5;241m.\u001b[39mload_image(\u001b[38;5;124m\"\u001b[39m\u001b[38;5;124mimage1\u001b[39m\u001b[38;5;124m\"\u001b[39m)\n\u001b[0;32m      2\u001b[0m face_locations \u001b[38;5;241m=\u001b[39m fr\u001b[38;5;241m.\u001b[39mface_locations(image)\n",
      "\u001b[1;31mAttributeError\u001b[0m: module 'face_recognition' has no attribute 'load_image'"
     ]
    }
   ],
   "source": [
    "image= fr.load_image(\"image1\")\n",
    "face_locations = fr.face_locations(image)"
   ]
  },
  {
   "cell_type": "code",
   "execution_count": 15,
   "id": "a06fbed1",
   "metadata": {},
   "outputs": [
    {
     "ename": "FileNotFoundError",
     "evalue": "[Errno 2] No such file or directory: 'image1'",
     "output_type": "error",
     "traceback": [
      "\u001b[1;31m---------------------------------------------------------------------------\u001b[0m",
      "\u001b[1;31mFileNotFoundError\u001b[0m                         Traceback (most recent call last)",
      "Cell \u001b[1;32mIn[15], line 1\u001b[0m\n\u001b[1;32m----> 1\u001b[0m image\u001b[38;5;241m=\u001b[39m fr\u001b[38;5;241m.\u001b[39mload_image_file(\u001b[38;5;124m\"\u001b[39m\u001b[38;5;124mimage1\u001b[39m\u001b[38;5;124m\"\u001b[39m)\n\u001b[0;32m      2\u001b[0m face_locations \u001b[38;5;241m=\u001b[39m fr\u001b[38;5;241m.\u001b[39mface_locations(image)\n",
      "File \u001b[1;32m~\\anaconda3\\Lib\\site-packages\\face_recognition\\api.py:86\u001b[0m, in \u001b[0;36mload_image_file\u001b[1;34m(file, mode)\u001b[0m\n\u001b[0;32m     78\u001b[0m \u001b[38;5;28;01mdef\u001b[39;00m \u001b[38;5;21mload_image_file\u001b[39m(file, mode\u001b[38;5;241m=\u001b[39m\u001b[38;5;124m'\u001b[39m\u001b[38;5;124mRGB\u001b[39m\u001b[38;5;124m'\u001b[39m):\n\u001b[0;32m     79\u001b[0m \u001b[38;5;250m    \u001b[39m\u001b[38;5;124;03m\"\"\"\u001b[39;00m\n\u001b[0;32m     80\u001b[0m \u001b[38;5;124;03m    Loads an image file (.jpg, .png, etc) into a numpy array\u001b[39;00m\n\u001b[0;32m     81\u001b[0m \n\u001b[1;32m   (...)\u001b[0m\n\u001b[0;32m     84\u001b[0m \u001b[38;5;124;03m    :return: image contents as numpy array\u001b[39;00m\n\u001b[0;32m     85\u001b[0m \u001b[38;5;124;03m    \"\"\"\u001b[39;00m\n\u001b[1;32m---> 86\u001b[0m     im \u001b[38;5;241m=\u001b[39m PIL\u001b[38;5;241m.\u001b[39mImage\u001b[38;5;241m.\u001b[39mopen(file)\n\u001b[0;32m     87\u001b[0m     \u001b[38;5;28;01mif\u001b[39;00m mode:\n\u001b[0;32m     88\u001b[0m         im \u001b[38;5;241m=\u001b[39m im\u001b[38;5;241m.\u001b[39mconvert(mode)\n",
      "File \u001b[1;32m~\\anaconda3\\Lib\\site-packages\\PIL\\Image.py:3227\u001b[0m, in \u001b[0;36mopen\u001b[1;34m(fp, mode, formats)\u001b[0m\n\u001b[0;32m   3224\u001b[0m     filename \u001b[38;5;241m=\u001b[39m fp\n\u001b[0;32m   3226\u001b[0m \u001b[38;5;28;01mif\u001b[39;00m filename:\n\u001b[1;32m-> 3227\u001b[0m     fp \u001b[38;5;241m=\u001b[39m builtins\u001b[38;5;241m.\u001b[39mopen(filename, \u001b[38;5;124m\"\u001b[39m\u001b[38;5;124mrb\u001b[39m\u001b[38;5;124m\"\u001b[39m)\n\u001b[0;32m   3228\u001b[0m     exclusive_fp \u001b[38;5;241m=\u001b[39m \u001b[38;5;28;01mTrue\u001b[39;00m\n\u001b[0;32m   3230\u001b[0m \u001b[38;5;28;01mtry\u001b[39;00m:\n",
      "\u001b[1;31mFileNotFoundError\u001b[0m: [Errno 2] No such file or directory: 'image1'"
     ]
    }
   ],
   "source": [
    "image= fr.load_image_file(\"image1\")\n",
    "face_locations = fr.face_locations(image)"
   ]
  },
  {
   "cell_type": "code",
   "execution_count": 16,
   "id": "92dff19d",
   "metadata": {},
   "outputs": [],
   "source": [
    "image= fr.load_image_file(\"image1.png\")\n",
    "face_locations = fr.face_locations(image)"
   ]
  },
  {
   "cell_type": "code",
   "execution_count": 17,
   "id": "e93ff2f2",
   "metadata": {},
   "outputs": [
    {
     "name": "stdout",
     "output_type": "stream",
     "text": [
      "Emplacement du visage : Haut=32, Droite=487, Bas=94, Gauche=425\n",
      "Emplacement du visage : Haut=58, Droite=121, Bas=94, Gauche=85\n",
      "Emplacement du visage : Haut=149, Droite=494, Bas=211, Gauche=432\n",
      "Nombre total de visages détectés : 3\n"
     ]
    }
   ],
   "source": [
    "import face_recognition\n",
    "\n",
    "# Charger l'image depuis le fichier\n",
    "image = face_recognition.load_image_file(\"image1.png\")\n",
    "\n",
    "# Détecter les emplacements des visages dans l'image\n",
    "face_locations = face_recognition.face_locations(image)\n",
    "\n",
    "# Imprimer les coordonnées de chaque visage détecté\n",
    "for face_location in face_locations:\n",
    "    top, right, bottom, left = face_location\n",
    "    print(f\"Emplacement du visage : Haut={top}, Droite={right}, Bas={bottom}, Gauche={left}\")\n",
    "\n",
    "# Optionnel : Vous pouvez également afficher le nombre total de visages détectés\n",
    "print(f\"Nombre total de visages détectés : {len(face_locations)}\")\n"
   ]
  },
  {
   "cell_type": "code",
   "execution_count": null,
   "id": "4370eacb",
   "metadata": {},
   "outputs": [],
   "source": [
    "import face_recognition\n",
    "known_image = face_recognition.load_file_image(\"image1.png\")\n",
    "unkown_image=face_recognition.load_file_image(\"image2.png\")\n",
    "biden_encoding=face_recognition.face_encodings(known_image)(0)\n",
    "unkown_image_encodings=face_recognition.face_encodings(unkown_image)(0)\n",
    "resultats=face_recognitions.compare_faces([biden_encoding],[unkown_image_encodings])"
   ]
  }
 ],
 "metadata": {
  "kernelspec": {
   "display_name": "Python 3 (ipykernel)",
   "language": "python",
   "name": "python3"
  },
  "language_info": {
   "codemirror_mode": {
    "name": "ipython",
    "version": 3
   },
   "file_extension": ".py",
   "mimetype": "text/x-python",
   "name": "python",
   "nbconvert_exporter": "python",
   "pygments_lexer": "ipython3",
   "version": "3.11.5"
  }
 },
 "nbformat": 4,
 "nbformat_minor": 5
}
